mplus_output/bi-03-HRS_W6.out
Mplus VERSION 8.1 (Mac)
MUTHEN & MUTHEN
05/27/2020  10:28 PM

INPUT INSTRUCTIONS

  DATA:
  FILE = "bi-03-HRS_W6.dat";

  VARIABLE:
  NAMES = mplusid UDAT UDAY UMON UYER UIWR UDWR USUB UBAK UNM1 UNM2 UNM5 UNM6;
   MISSING=.;
   CATEGORICAL ARE all; idvariable = mplusid;
  ANALYSIS:
  estimator = wlsmv; coverage=0;
  MODEL:
  g by UDAT * ;
   g by UDAY * ;
   g by UMON * ;
   g by UYER * ;
   g by UIWR * ;
   g by UDWR * ;
   g by USUB * ;
   g by UBAK * ;
   g by UNM1 * ;
   g by UNM2 * ;
   g by UNM5 * ;
   g by UNM6 * ;
   s1 by UIWR @ 1 ;
   s1 by UDWR @ 1 ;
   g @ 1;
   s1 * ;
   g with s1 @ 0 ;

  OUTPUT:
  standardized; svalues;



*** WARNING
  Data set contains cases with missing on all variables.
  These cases were not included in the analysis.
  Number of cases with missing on all variables:  1940
   1 WARNING(S) FOUND IN THE INPUT INSTRUCTIONS




SUMMARY OF ANALYSIS

Number of groups                                                 1
Number of observations                                       17124

Number of dependent variables                                   12
Number of independent variables                                  0
Number of continuous latent variables                            2

Observed dependent variables

  Binary and ordered categorical (ordinal)
   UDAT        UDAY        UMON        UYER        UIWR        UDWR
   USUB        UBAK        UNM1        UNM2        UNM5        UNM6

Continuous latent variables
   G           S1

Variables with special functions

  ID variable           MPLUSID

Estimator                                                    WLSMV
Maximum number of iterations                                  1000
Convergence criterion                                    0.500D-04
Maximum number of steepest descent iterations                   20
Maximum number of iterations for H1                           2000
Convergence criterion for H1                             0.100D-03
Parameterization                                             DELTA
Link                                                        PROBIT

Input data file(s)
  bi-03-HRS_W6.dat

Input data format  FREE


SUMMARY OF DATA

     Number of missing data patterns           108


COVARIANCE COVERAGE OF DATA

Minimum covariance coverage value   0.000


     PROPORTION OF DATA PRESENT


           Covariance Coverage
              UDAT          UDAY          UMON          UYER          UIWR
              ________      ________      ________      ________      ________
 UDAT           0.590
 UDAY           0.590         0.591
 UMON           0.589         0.590         0.590
 UYER           0.590         0.590         0.590         0.590
 UIWR           0.578         0.579         0.579         0.579         0.985
 UDWR           0.530         0.531         0.531         0.531         0.926
 USUB           0.539         0.540         0.540         0.540         0.918
 UBAK           0.584         0.585         0.584         0.584         0.980
 UNM1           0.589         0.590         0.589         0.589         0.579
 UNM2           0.575         0.575         0.575         0.575         0.566
 UNM5           0.584         0.585         0.585         0.585         0.575
 UNM6           0.567         0.567         0.567         0.567         0.558


           Covariance Coverage
              UDWR          USUB          UBAK          UNM1          UNM2
              ________      ________      ________      ________      ________
 UDWR           0.926
 USUB           0.871         0.925
 UBAK           0.923         0.923         0.993
 UNM1           0.531         0.540         0.585         0.591
 UNM2           0.521         0.530         0.571         0.576         0.576
 UNM5           0.528         0.537         0.580         0.586         0.572
 UNM6           0.514         0.524         0.563         0.568         0.558


           Covariance Coverage
              UNM5          UNM6
              ________      ________
 UNM5           0.586
 UNM6           0.567         0.568


UNIVARIATE PROPORTIONS AND COUNTS FOR CATEGORICAL VARIABLES

    UDAT
      Category 1    0.173         1752.000
      Category 2    0.827         8350.000
    UDAY
      Category 1    0.032          320.000
      Category 2    0.968         9796.000
    UMON
      Category 1    0.027          276.000
      Category 2    0.973         9829.000
    UYER
      Category 1    0.036          365.000
      Category 2    0.964         9746.000
    UIWR
      Category 1    0.001           13.000
      Category 2    0.012          196.000
      Category 3    0.028          475.000
      Category 4    0.067         1123.000
      Category 5    0.129         2176.000
      Category 6    0.426         7179.000
      Category 7    0.175         2946.000
      Category 8    0.104         1755.000
      Category 9    0.043          729.000
      Category 10    0.016          277.000
    UDWR
      Category 1    0.003           44.000
      Category 2    0.039          617.000
      Category 3    0.066         1047.000
      Category 4    0.124         1969.000
      Category 5    0.182         2889.000
      Category 6    0.379         6017.000
      Category 7    0.108         1712.000
      Category 8    0.058          923.000
      Category 9    0.028          438.000
      Category 10    0.013          209.000
    USUB
      Category 1    0.041          649.000
      Category 2    0.097         1543.000
      Category 3    0.082         1301.000
      Category 4    0.131         2082.000
      Category 5    0.205         3243.000
      Category 6    0.443         7017.000
    UBAK
      Category 1    0.044          753.000
      Category 2    0.956        16246.000
    UNM1
      Category 1    0.009           89.000
      Category 2    0.991        10026.000
    UNM2
      Category 1    0.078          768.000
      Category 2    0.922         9098.000
    UNM5
      Category 1    0.037          368.000
      Category 2    0.963         9667.000
    UNM6
      Category 1    0.132         1286.000
      Category 2    0.868         8442.000



THE MODEL ESTIMATION TERMINATED NORMALLY



MODEL FIT INFORMATION

Number of Free Parameters                       45

Chi-Square Test of Model Fit

          Value                            642.477*
          Degrees of Freedom                    53
          P-Value                           0.0000

*   The chi-square value for MLM, MLMV, MLR, ULSMV, WLSM and WLSMV cannot be used
    for chi-square difference testing in the regular way.  MLM, MLR and WLSM
    chi-square difference testing is described on the Mplus website.  MLMV, WLSMV,
    and ULSMV difference testing is done using the DIFFTEST option.

RMSEA (Root Mean Square Error Of Approximation)

          Estimate                           0.025
          90 Percent C.I.                    0.024  0.027
          Probability RMSEA <= .05           1.000

CFI/TLI

          CFI                                0.991
          TLI                                0.989

Chi-Square Test of Model Fit for the Baseline Model

          Value                          66051.680
          Degrees of Freedom                    66
          P-Value                           0.0000

SRMR (Standardized Root Mean Square Residual)

          Value                              0.059

Optimum Function Value for Weighted Least-Squares Estimator

          Value                     0.14821804D-01



MODEL RESULTS

                                                    Two-Tailed
                    Estimate       S.E.  Est./S.E.    P-Value

 G        BY
    UDAT               0.551      0.015     37.163      0.000
    UDAY               0.726      0.021     34.790      0.000
    UMON               0.771      0.021     36.050      0.000
    UYER               0.874      0.018     49.918      0.000
    UIWR               0.567      0.009     61.727      0.000
    UDWR               0.464      0.012     39.392      0.000
